<?xml version="1.0" encoding="utf-8"?>
<!-- This URDF was automatically created by SolidWorks to URDF Exporter! Originally created by Stephen Brawner (brawner@gmail.com) 
     Commit Version: 1.6.0-1-g15f4949  Build Version: 1.6.7594.29634
     For more information, please see http://wiki.ros.org/sw_urdf_exporter -->
<robot
  name="xmate3p">
  <link
    name="base_link">
    <inertial>
      <origin
        xyz="-0.015091360234716 4.56135683096622E-05 0.0624086188001657"
        rpy="0 0 0" />
      <mass
        value="3.14897165663379" />
      <inertia
        ixx="0.0118099957881921"
        ixy="1.05329502958308E-05"
        ixz="-0.0018000843325847"
        iyy="0.0158485547388248"
        iyz="1.08029035443306E-06"
        izz="0.0129719574437711" />
    </inertial>
    <visual>
      <origin
        xyz="0 0 0"
        rpy="0 0 0" />
      <geometry>
        <mesh
          filename="package://model_description/xmate3p/meshes/base_link.STL" />
      </geometry>
      <material
        name="">
        <color
          rgba="1 1 1 1" />
      </material>
    </visual>
    <collision>
      <origin
        xyz="0 0 0"
        rpy="0 0 0" />
      <geometry>
        <mesh
          filename="package://model_description/xmate3p/meshes/base_link.STL" />
      </geometry>
    </collision>
  </link>
  <link
    name="link1">
    <inertial>
      <origin
        xyz="-0.00025922 -0.025215 0.11962"
        rpy="0 0 0" />
      <mass
        value="1.8004" />
      <inertia
        ixx="0.0095699"
        ixy="-5.5922E-07"
        ixz="-5.8571E-07"
        iyy="0.0085643"
        iyz="0.0019573"
        izz="0.0033056" />
    </inertial>
    <visual>
      <origin
        xyz="0 0 0"
        rpy="0 0 0" />
      <geometry>
        <mesh
          filename="package://model_description/xmate3p/meshes/link1.STL" />
      </geometry>
      <material
        name="">
        <color
          rgba="1 1 1 1" />
      </material>
    </visual>
    <collision>
      <origin
        xyz="0 0 0"
        rpy="0 0 0" />
      <geometry>
        <mesh
          filename="package://model_description/xmate3p/meshes/link1.STL" />
      </geometry>
    </collision>
  </link>
  <joint
    name="joint1"
    type="revolute">
    <origin
      xyz="0.0042608 -5.9631E-05 0.16844"
      rpy="0 0 0" />
    <parent
      link="base_link" />
    <child
      link="link1" />
    <axis
      xyz="0 0 1" />
    <limit
      lower="-2.967"
      upper="2.967"
      effort="100"
      velocity="100" />
  </joint>
  <link
    name="link2">
    <inertial>
      <origin
        xyz="-7.71963204856322E-06 0.00806548573205907 0.0949824454097805"
        rpy="0 0 0" />
      <mass
        value="2.1851012084317" />
      <inertia
        ixx="0.0179598444816337"
        ixy="6.72005684992317E-07"
        ixz="-1.92493798049796E-07"
        iyy="0.0162934935793924"
        iyz="0.00456695536940276"
        izz="0.00446693295470817" />
    </inertial>
    <visual>
      <origin
        xyz="0 0 0"
        rpy="0 0 0" />
      <geometry>
        <mesh
          filename="package://model_description/xmate3p/meshes/link2.STL" />
      </geometry>
      <material
        name="">
        <color
          rgba="1 1 1 1" />
      </material>
    </visual>
    <collision>
      <origin
        xyz="0 0 0"
        rpy="0 0 0" />
      <geometry>
        <mesh
          filename="package://model_description/xmate3p/meshes/link2.STL" />
      </geometry>
    </collision>
  </link>
  <joint
    name="joint2"
    type="revolute">
    <origin
      xyz="-0.00026107 0.019633 0.17276"
      rpy="0 0 0" />
    <parent
      link="link1" />
    <child
      link="link2" />
    <axis
      xyz="0 1 0" />
    <limit
      lower="-2.094"
      upper="2.094"
      effort="100"
      velocity="100" />
  </joint>
  <link
    name="link3">
    <inertial>
      <origin
        xyz="1.83491748824072E-06 -0.025268072019476 0.106954324405955"
        rpy="0 0 0" />
      <mass
        value="1.80045507711239" />
      <inertia
        ixx="0.009570539674734"
        ixy="-5.63735078403178E-07"
        ixz="-6.0500648082681E-07"
        iyy="0.00856439929687802"
        iyz="0.00195821644467193"
        izz="0.00330613229822486" />
    </inertial>
    <visual>
      <origin
        xyz="0 0 0"
        rpy="0 0 0" />
      <geometry>
        <mesh
          filename="package://model_description/xmate3p/meshes/link3.STL" />
      </geometry>
      <material
        name="">
        <color
          rgba="1 1 1 1" />
      </material>
    </visual>
    <collision>
      <origin
        xyz="0 0 0"
        rpy="0 0 0" />
      <geometry>
        <mesh
          filename="package://model_description/xmate3p/meshes/link3.STL" />
      </geometry>
    </collision>
  </link>
  <joint
    name="joint3"
    type="revolute">
    <origin
      xyz="0 -0.019574 0.2339"
      rpy="0 0 0" />
    <parent
      link="link2" />
    <child
      link="link3" />
    <axis
      xyz="0 0 1" />
    <limit
      lower="-2.967"
      upper="2.967"
      effort="100"
      velocity="100" />
  </joint>
  <link
    name="link4">
    <inertial>
      <origin
        xyz="2.6565854771058E-06 0.0133168201264488 0.0756674818518959"
        rpy="0 0 0" />
      <mass
        value="1.80003368124098" />
      <inertia
        ixx="0.0130994533098041"
        ixy="1.36284854708963E-07"
        ixz="-5.92055668378373E-07"
        iyy="0.0117535662054175"
        iyz="0.00347706804921294"
        izz="0.00336527705329235" />
    </inertial>
    <visual>
      <origin
        xyz="0 0 0"
        rpy="0 0 0" />
      <geometry>
        <mesh
          filename="package://model_description/xmate3p/meshes/link4.STL" />
      </geometry>
      <material
        name="">
        <color
          rgba="1 1 1 1" />
      </material>
    </visual>
    <collision>
      <origin
        xyz="0 0 0"
        rpy="0 0 0" />
      <geometry>
        <mesh
          filename="package://model_description/xmate3p/meshes/link4.STL" />
      </geometry>
    </collision>
  </link>
  <joint
    name="joint4"
    type="revolute">
    <origin
      xyz="0 0.0196 0.1604"
      rpy="0 0 0" />
    <parent
      link="link3" />
    <child
      link="link4" />
    <axis
      xyz="0 1 0" />
    <limit
      lower="-2.094"
      upper="2.094"
      effort="100"
      velocity="100" />
  </joint>
  <link
    name="link5">
    <inertial>
      <origin
        xyz="1.25130563160484E-05 -0.0312770106676637 0.10470207994546"
        rpy="0 0 0" />
      <mass
        value="1.29595892372392" />
      <inertia
        ixx="0.00598570038305338"
        ixy="-4.67875753164966E-07"
        ixz="5.61444849450011E-07"
        iyy="0.00489860850115636"
        iyz="0.00152659864778688"
        izz="0.00226768548743438" />
    </inertial>
    <visual>
      <origin
        xyz="0 0 0"
        rpy="0 0 0" />
      <geometry>
        <mesh
          filename="package://model_description/xmate3p/meshes/link5.STL" />
      </geometry>
      <material
        name="">
        <color
          rgba="1 1 1 1" />
      </material>
    </visual>
    <collision>
      <origin
        xyz="0 0 0"
        rpy="0 0 0" />
      <geometry>
        <mesh
          filename="package://model_description/xmate3p/meshes/link5.STL" />
      </geometry>
    </collision>
  </link>
  <joint
    name="joint5"
    type="revolute">
    <origin
      xyz="0 -0.0196 0.2156"
      rpy="0 0 0" />
    <parent
      link="link4" />
    <child
      link="link5" />
    <axis
      xyz="0 0 1" />
    <limit
      lower="-2.967"
      upper="2.967"
      effort="100"
      velocity="100" />
  </joint>
  <link
    name="link6">
    <inertial>
      <origin
        xyz="1.11743579776372E-05 0.00542778918890232 0.0842925312965763"
        rpy="0 0 0" />
      <mass
        value="1.22513525609944" />
      <inertia
        ixx="0.0062839615268434"
        ixy="-1.43677994204335E-07"
        ixz="3.43793365441653E-07"
        iyy="0.00598571888406249"
        iyz="0.00128424062046448"
        izz="0.00146487804256938" />
    </inertial>
    <visual>
      <origin
        xyz="0 0 0"
        rpy="0 0 0" />
      <geometry>
        <mesh
          filename="package://model_description/xmate3p/meshes/link6.STL" />
      </geometry>
      <material
        name="">
        <color
          rgba="1 1 1 1" />
      </material>
    </visual>
    <collision>
      <origin
        xyz="0 0 0"
        rpy="0 0 0" />
      <geometry>
        <mesh
          filename="package://model_description/xmate3p/meshes/link6.STL" />
      </geometry>
    </collision>
  </link>
  <joint
    name="joint6"
    type="revolute">
    <origin
      xyz="0 0.00972 0.1504"
      rpy="0 0 0" />
    <parent
      link="link5" />
    <child
      link="link6" />
    <axis
      xyz="0 1 0" />
    <limit
      lower="-2.094"
      upper="2.094"
      effort="100"
      velocity="100" />
  </joint>
  <link
    name="link7">
    <inertial>
      <origin
        xyz="4.62021200668606E-05 0.0230545844058025 -0.0447538097295144"
        rpy="0 0 0" />
      <mass
        value="0.542707965692323" />
      <inertia
        ixx="0.00116620579896998"
        ixy="-2.34444546578733E-07"
        ixz="-4.26342180924484E-07"
        iyy="0.000638472104930667"
        iyz="0.000282302091216014"
        izz="0.000951797511362842" />
    </inertial>
    <visual>
      <origin
        xyz="0 0 0"
        rpy="0 0 0" />
      <geometry>
        <mesh
          filename="package://model_description/xmate3p/meshes/link7.STL" />
      </geometry>
      <material
        name="">
        <color
          rgba="1 1 1 1" />
      </material>
    </visual>
    <collision>
      <origin
        xyz="0 0 0"
        rpy="0 0 0" />
      <geometry>
        <mesh
          filename="package://model_description/xmate3p/meshes/link7.STL" />
      </geometry>
    </collision>
  </link>
  <joint
    name="joint7"
    type="revolute">
    <origin
      xyz="0 -0.00972 0.2503"
      rpy="0 0 0" />
    <parent
      link="link6" />
    <child
      link="link7" />
    <axis
      xyz="0 0 1" />
    <limit
      lower="-2.967"
      upper="2.967"
      effort="100"
      velocity="100" />
  </joint>
</robot>
